try{
	%|
}catch(std::exception e){
	
}catch(...){
	
}